<?xml version = "1.0"?>

<robot name = "inchworm" xmlns:xacro="http://www.ros.org/wiki/xacro">
  <link name = "inchworm">
    <visual>
      <origin xyz="0 0 0" rpy="0 0 0"/>
      <geometry>
        <mesh filename="package://spirits_description/meshes/inchworm_color.dae" scale="0.001 0.001 0.001"/>
      </geometry>
    </visual>

    <collision>
      <origin xyz="0 0 0" rpy="0 0 0"/>
      <geometry>
        <mesh filename="package://spirits_description/meshes/inchworm.dae" scale="0.001 0.001 0.001"/>
      </geometry>
    </collision>
  </link>

  <link name = "needle">
    <visual>
      <origin xyz="0 0 0" rpy="0 0 0"/>
      <geometry>
        <mesh filename="package://spirits_description/meshes/needle_color.dae" scale="0.001 0.001 0.001"/>
      </geometry>
    </visual>

    <collision>
      <origin xyz="0 0 0" rpy="0 0 0"/>
      <geometry>
        <mesh filename="package://spirits_description/meshes/needle.dae" scale="0.001 0.001 0.001"/>
      </geometry>
    </collision>
  </link>

  <link name="tool0"/>


  <joint name="l22inch" type="fixed">
    <parent link="link2"/>
    <child link="inchworm"/>
    <origin xyz="0.0496053 0.0 0.0262441" rpy="0 -0.9075717 0.0"/>
  </joint> 

  <joint name="joint3" type="prismatic">
      <origin rpy="0 0 0" xyz="0 0 0.06295"/>
      <parent link="inchworm"/>
      <child link="needle"/>
      <axis xyz="0 0 1"/>
      <limit velocity="4.8" effort="1" lower="-0.01" upper="0.08" />
  </joint>

  <joint name="tool02needle" type="fixed">
      <origin rpy="0 0 0" xyz="0 0 0"/>
      <parent link="needle"/>
      <child link="tool0"/>
      <axis xyz="0 0 0"/>
  </joint>
</robot>