<?xml version = "1.0"?>
<robot name = "spirits" xmlns:xacro="http://www.ros.org/wiki/xacro">

  <!-- Used for fixing robot to 'base_link' -->
  <link name="world"/>

  <!-- Base Link -->
  <link name = "base_link">
    <visual>
      <origin xyz="0 0 0" rpy="0 0 0"/>
      <geometry>
        <mesh filename="package://spirits_description/meshes/bw_base_color.dae" scale="0.001 0.001 0.001"/>
      </geometry>
    </visual>

    <collision>
      <origin xyz="0 0 0" rpy="0 0 0"/>
      <geometry>
        <mesh filename="package://spirits_description/meshes/bw_base.dae" scale="0.001 0.001 0.001"/>
      </geometry>
    </collision>
  </link>


  <link name = "link1">
    <visual>
      <origin xyz="0 0 0" rpy="0 0 0"/>
      <geometry>
        <mesh filename="package://spirits_description/meshes/bras_1_color.dae" scale="0.001 0.001 0.001"/>
      </geometry>
    </visual>

    <collision>
      <origin xyz="0 0 0" rpy="0 0 0"/>
      <geometry>
        <mesh filename="package://spirits_description/meshes/bras_1.dae" scale="0.001 0.001 0.001"/>
      </geometry>
    </collision>
  </link>

  <link name = "link2">
    <visual>
      <origin xyz="0 0 0" rpy="0 0 0"/>
      <geometry>
        <mesh filename="package://spirits_description/meshes/bras_2_color.dae" scale="0.001 0.001 0.001"/>
      </geometry>
    </visual>

    <collision>
      <origin xyz="0 0 0" rpy="0 0 0"/>
      <geometry>
        <mesh filename="package://spirits_description/meshes/bras_2.dae" scale="0.001 0.001 0.001"/>
      </geometry>
    </collision>
  </link>


  <joint name="base2world" type="fixed">
    <parent link="world"/>
    <child link="base_link"/>
    <origin xyz="0 0 0" rpy="1.5707 0 0"/>
  </joint>

  <joint name="joint1" type="revolute">
    <parent link="base_link"/>
    <child link="link1"/>
    <origin xyz="0.0 0.0168232 0.0627852" rpy="3.0205411 0.2327037 1.0853922"/>
    <axis xyz="0 0 1"/>
    <limit velocity="4.8" effort="1" lower="-0.6" upper="0.6" />
  </joint>

  <joint name="joint2" type="revolute">
    <parent link="link1"/>
    <child link="link2"/>
    <origin xyz="0.0627852 0.0 0.0481768" rpy="1.3086534 -0.0505738 -1.5572328"/>
    <axis xyz="0 0 1"/>
    <limit velocity="4.8" effort="1" lower="-0.8" upper="0.8" />
  </joint>

  

</robot>

